2024-08-12 18:48:20,748 - ERROR - Uncaught exception
Traceback (most recent call last):
  File "C:\Users\Michael\Documents\GitHub\ssicsync\main.py", line 9, in <module>
    modelResults.runValidatingClassificationModel()
  File "C:\Users\Michael\Documents\GitHub\ssicsync\controller.py", line 15, in runValidatingClassificationModel
    validatingClassificationModel(self)
  File "C:\Users\Michael\Documents\GitHub\ssicsync\models\classificationModel\validatingClassificationModel.py", line 323, in validatingClassificationModel
    vdf.tocsv('models/classificationModel/modelOutputFiles/pdfModelFinalOutputs.csv', index=False)
  File "C:\Users\Michael\AppData\Roaming\Python\Python310\site-packages\pandas\core\generic.py", line 5989, in __getattr__
    return object.__getattribute__(self, name)
AttributeError: 'DataFrame' object has no attribute 'tocsv'
