2024-08-12 19:20:14,555 - INFO - Start code execution.
2024-08-12 19:20:14,572 - ERROR - Uncaught exception
Traceback (most recent call last):
  File "C:\Users\Michael\Documents\GitHub\ssicsync\main.py", line 10, in <module>
    modelResults.runValidatingClassificationModel()
  File "C:\Users\Michael\Documents\GitHub\ssicsync\controller.py", line 15, in runValidatingClassificationModel
    validatingClassificationModel(self)
  File "C:\Users\Michael\Documents\GitHub\ssicsync\models\classificationModel\validatingClassificationModel.py", line 142, in validatingClassificationModel
    ssic_1, ssic_2, ssic_3, ssic_4, ssic_5, ssic_df = ssic_df(ssic_detailed_def_filepath, ssic_alpha_index_filepath)
UnboundLocalError: local variable 'ssic_df' referenced before assignment
