2024-09-01 22:18:15,112 - INFO - Start code execution ...
2024-09-01 22:50:30,633 - INFO - Summary Outputs CSV generated.
2024-09-01 22:52:33,011 - ERROR - Uncaught exception
Traceback (most recent call last):
  File "C:\Users\Michael\Documents\GitHub\ssicsync\main.py", line 31, in <module>
    modelResults.runValidatingClassificationModel(logger, ssic_detailed_def_filepath, ssic_alpha_index_filepath, companies_filepath)
  File "C:\Users\Michael\Documents\GitHub\ssicsync\controller.py", line 42, in runValidatingClassificationModel
    validatingClassificationModel(self, logger, ssic_detailed_def_filepath, ssic_alpha_index_filepath, companies_filepath)
  File "C:\Users\Michael\Documents\GitHub\ssicsync\models\classificationModel\validatingClassificationModel.py", line 479, in validatingClassificationModel
    vdf = calculatePredictionScore(vdf, ssic_1)
  File "C:\Users\Michael\Documents\GitHub\ssicsync\models\classificationModel\validatingClassificationModel.py", line 344, in calculatePredictionScore
    predictionScore = df.apply(calculateInverseScore, axis = 1, scoreCurve = 5, refTable = refTable)
  File "C:\Users\Michael\AppData\Roaming\Python\Python310\site-packages\pandas\core\frame.py", line 9423, in apply
    return op.apply().__finalize__(self, method="apply")
  File "C:\Users\Michael\AppData\Roaming\Python\Python310\site-packages\pandas\core\apply.py", line 678, in apply
    return self.apply_standard()
  File "C:\Users\Michael\AppData\Roaming\Python\Python310\site-packages\pandas\core\apply.py", line 798, in apply_standard
    results, res_index = self.apply_series_generator()
  File "C:\Users\Michael\AppData\Roaming\Python\Python310\site-packages\pandas\core\apply.py", line 814, in apply_series_generator
    results[i] = self.f(v)
  File "C:\Users\Michael\AppData\Roaming\Python\Python310\site-packages\pandas\core\apply.py", line 133, in f
    return func(x, *args, **kwargs)
  File "C:\Users\Michael\Documents\GitHub\ssicsync\models\classificationModel\validatingClassificationModel.py", line 212, in calculateInverseScore
    predictedList = ast.literal_eval(row[f'p_{modelChoice}'])   # extract predicted ssic codes
  File "C:\Program Files\Python310\lib\ast.py", line 110, in literal_eval
    return _convert(node_or_string)
  File "C:\Program Files\Python310\lib\ast.py", line 109, in _convert
    return _convert_signed_num(node)
  File "C:\Program Files\Python310\lib\ast.py", line 83, in _convert_signed_num
    return _convert_num(node)
  File "C:\Program Files\Python310\lib\ast.py", line 74, in _convert_num
    _raise_malformed_node(node)
  File "C:\Program Files\Python310\lib\ast.py", line 71, in _raise_malformed_node
    raise ValueError(msg + f': {node!r}')
ValueError: malformed node or string: ['472', '561', '107']
