2024-08-22 01:16:41,028 - INFO - Start code execution.
2024-08-22 01:33:05,849 - ERROR - Uncaught exception
Traceback (most recent call last):
  File "C:\Users\Michael\Documents\GitHub\ssicsync\main.py", line 20, in <module>
    modelResults.runValidatingClassificationModel(logger)
  File "C:\Users\Michael\Documents\GitHub\ssicsync\controller.py", line 92, in runValidatingClassificationModel
    validatingClassificationModel(self, logger)
  File "C:\Users\Michael\Documents\GitHub\ssicsync\models\classificationModel\validatingClassificationModel.py", line 336, in validatingClassificationModel
    # modelOutputs_df['SSIC 1 Title'] = modelOutputs_df['SSIC 1'].apply(lambda x: capitalize_sentence(ssic_dataframe.loc[ssic_dataframe['SSIC 2020'] == x, 'Section Title'].values[0]))
  File "C:\Users\Michael\Documents\GitHub\ssicsync\models\classificationModel\validatingClassificationModel.py", line 336, in validatingClassificationModel
    # modelOutputs_df['SSIC 1 Title'] = modelOutputs_df['SSIC 1'].apply(lambda x: capitalize_sentence(ssic_dataframe.loc[ssic_dataframe['SSIC 2020'] == x, 'Section Title'].values[0]))
  File "C:\Program Files\Python310\lib\bdb.py", line 90, in trace_dispatch
    return self.dispatch_line(frame)
  File "C:\Program Files\Python310\lib\bdb.py", line 115, in dispatch_line
    if self.quitting: raise BdbQuit
bdb.BdbQuit
