2024-08-21 23:49:57,062 - INFO - Start code execution.
2024-08-22 00:15:24,295 - ERROR - Uncaught exception
Traceback (most recent call last):
  File "C:\Users\Michael\Documents\GitHub\ssicsync\main.py", line 20, in <module>
    modelResults.runValidatingClassificationModel(logger)
  File "C:\Users\Michael\Documents\GitHub\ssicsync\controller.py", line 92, in runValidatingClassificationModel
    validatingClassificationModel(self, logger)
  File "C:\Users\Michael\Documents\GitHub\ssicsync\models\classificationModel\validatingClassificationModel.py", line 300, in validatingClassificationModel
    modelOutputs_df['SSIC 1'] = modelOutputs_df['SSIC 1'].apply(lambda x: str(x).zfill(5))
  File "C:\Users\Michael\Documents\GitHub\ssicsync\models\classificationModel\validatingClassificationModel.py", line 300, in validatingClassificationModel
    modelOutputs_df['SSIC 1'] = modelOutputs_df['SSIC 1'].apply(lambda x: str(x).zfill(5))
  File "C:\Program Files\Python310\lib\bdb.py", line 90, in trace_dispatch
    return self.dispatch_line(frame)
  File "C:\Program Files\Python310\lib\bdb.py", line 115, in dispatch_line
    if self.quitting: raise BdbQuit
bdb.BdbQuit
