2024-08-22 01:56:09,768 - INFO - Start code execution.
2024-08-22 02:11:54,591 - ERROR - Uncaught exception
Traceback (most recent call last):
  File "C:\Users\Michael\Documents\GitHub\ssicsync\main.py", line 20, in <module>
    modelResults.runValidatingClassificationModel(logger)
  File "C:\Users\Michael\Documents\GitHub\ssicsync\controller.py", line 92, in runValidatingClassificationModel
    validatingClassificationModel(self, logger)
  File "C:\Users\Michael\Documents\GitHub\ssicsync\models\classificationModel\validatingClassificationModel.py", line 357, in validatingClassificationModel
    modelOutputs_df = pd.concat([modelOutputs_df, description_df], axis=1)
  File "C:\Program Files\Python310\lib\bdb.py", line 94, in trace_dispatch
    return self.dispatch_return(frame, arg)
  File "C:\Program Files\Python310\lib\bdb.py", line 156, in dispatch_return
    if self.quitting: raise BdbQuit
bdb.BdbQuit
