2024-08-22 00:48:59,775 - INFO - Start code execution.
2024-08-22 01:13:49,834 - ERROR - Uncaught exception
Traceback (most recent call last):
  File "C:\Users\Michael\Documents\GitHub\ssicsync\main.py", line 20, in <module>
    modelResults.runValidatingClassificationModel(logger)
  File "C:\Users\Michael\Documents\GitHub\ssicsync\controller.py", line 92, in runValidatingClassificationModel
    validatingClassificationModel(self, logger)
  File "C:\Users\Michael\Documents\GitHub\ssicsync\models\classificationModel\validatingClassificationModel.py", line 328, in validatingClassificationModel
    # company # notes page content # SSIC 1 # SSIC 2 # SSIC 1 Description # SSIC 2 Description # Recommended SSICs # Recommended SSIC Descriptions
  File "C:\Program Files\Python310\lib\bdb.py", line 94, in trace_dispatch
    return self.dispatch_return(frame, arg)
  File "C:\Program Files\Python310\lib\bdb.py", line 156, in dispatch_return
    if self.quitting: raise BdbQuit
bdb.BdbQuit
