2024-08-22 00:40:29,340 - INFO - Start code execution.
2024-08-22 00:48:36,012 - ERROR - Uncaught exception
Traceback (most recent call last):
  File "C:\Users\Michael\Documents\GitHub\ssicsync\main.py", line 20, in <module>
    modelResults.runValidatingClassificationModel(logger)
  File "C:\Users\Michael\Documents\GitHub\ssicsync\controller.py", line 92, in runValidatingClassificationModel
    validatingClassificationModel(self, logger)
  File "C:\Users\Michael\Documents\GitHub\ssicsync\models\classificationModel\validatingClassificationModel.py", line 313, in validatingClassificationModel
    elif resultsLevel == 'Group':
  File "C:\Program Files\Python310\lib\bdb.py", line 94, in trace_dispatch
    return self.dispatch_return(frame, arg)
  File "C:\Program Files\Python310\lib\bdb.py", line 156, in dispatch_return
    if self.quitting: raise BdbQuit
bdb.BdbQuit
