2024-08-22 01:36:58,389 - INFO - Start code execution.
2024-08-22 01:55:54,905 - ERROR - Uncaught exception
Traceback (most recent call last):
  File "C:\Users\Michael\Documents\GitHub\ssicsync\main.py", line 20, in <module>
    modelResults.runValidatingClassificationModel(logger)
  File "C:\Users\Michael\Documents\GitHub\ssicsync\controller.py", line 92, in runValidatingClassificationModel
    validatingClassificationModel(self, logger)
  File "C:\Users\Michael\Documents\GitHub\ssicsync\models\classificationModel\validatingClassificationModel.py", line 337, in validatingClassificationModel
    modelOutputs_df['SSIC 2 Description'] = modelOutputs_df['SSIC 2'].map(ssic_to_title).apply(lambda x: capitalize_sentence(x) if pd.notna(x) else np.NaN)
  File "C:\Users\Michael\Documents\GitHub\ssicsync\models\classificationModel\validatingClassificationModel.py", line 337, in validatingClassificationModel
    modelOutputs_df['SSIC 2 Description'] = modelOutputs_df['SSIC 2'].map(ssic_to_title).apply(lambda x: capitalize_sentence(x) if pd.notna(x) else np.NaN)
  File "C:\Program Files\Python310\lib\bdb.py", line 90, in trace_dispatch
    return self.dispatch_line(frame)
  File "C:\Program Files\Python310\lib\bdb.py", line 115, in dispatch_line
    if self.quitting: raise BdbQuit
bdb.BdbQuit
