2024-08-24 04:51:19,047 - INFO - Start code execution ...
2024-08-24 04:51:45,571 - ERROR - Uncaught exception
Traceback (most recent call last):
  File "C:\Users\Michael\AppData\Roaming\Python\Python310\site-packages\httpx\_transports\default.py", line 69, in map_httpcore_exceptions
    yield
  File "C:\Users\Michael\AppData\Roaming\Python\Python310\site-packages\httpx\_transports\default.py", line 233, in handle_request
    resp = self._pool.handle_request(req)
  File "C:\Users\Michael\AppData\Roaming\Python\Python310\site-packages\httpcore\_sync\connection_pool.py", line 216, in handle_request
    raise exc from None
  File "C:\Users\Michael\AppData\Roaming\Python\Python310\site-packages\httpcore\_sync\connection_pool.py", line 196, in handle_request
    response = connection.handle_request(
  File "C:\Users\Michael\AppData\Roaming\Python\Python310\site-packages\httpcore\_sync\connection.py", line 99, in handle_request
    raise exc
  File "C:\Users\Michael\AppData\Roaming\Python\Python310\site-packages\httpcore\_sync\connection.py", line 76, in handle_request
    stream = self._connect(request)
  File "C:\Users\Michael\AppData\Roaming\Python\Python310\site-packages\httpcore\_sync\connection.py", line 122, in _connect
    stream = self._network_backend.connect_tcp(**kwargs)
  File "C:\Users\Michael\AppData\Roaming\Python\Python310\site-packages\httpcore\_backends\sync.py", line 205, in connect_tcp
    with map_exceptions(exc_map):
  File "C:\Program Files\Python310\lib\contextlib.py", line 153, in __exit__
    self.gen.throw(typ, value, traceback)
  File "C:\Users\Michael\AppData\Roaming\Python\Python310\site-packages\httpcore\_exceptions.py", line 14, in map_exceptions
    raise to_exc(exc) from exc
httpcore.ConnectError: [WinError 10061] No connection could be made because the target machine actively refused it

The above exception was the direct cause of the following exception:

Traceback (most recent call last):
  File "C:\Users\Michael\Documents\GitHub\ssicsync\main.py", line 27, in <module>
    modelResults.runTrainingSummaryModel(logger)
  File "C:\Users\Michael\Documents\GitHub\ssicsync\controller.py", line 98, in runTrainingSummaryModel
    trainingSummaryModel(self, logger)
  File "C:\Users\Michael\Documents\GitHub\ssicsync\models\summaryModel\trainingSummaryModel.py", line 68, in trainingSummaryModel
    df_input['llm_output_llama3.1'] = df_input['Notes Page Content'].apply(lambda x: summarize_business_activity(x))
  File "C:\Users\Michael\AppData\Roaming\Python\Python310\site-packages\pandas\core\series.py", line 4630, in apply
    return SeriesApply(self, func, convert_dtype, args, kwargs).apply()
  File "C:\Users\Michael\AppData\Roaming\Python\Python310\site-packages\pandas\core\apply.py", line 1025, in apply
    return self.apply_standard()
  File "C:\Users\Michael\AppData\Roaming\Python\Python310\site-packages\pandas\core\apply.py", line 1076, in apply_standard
    mapped = lib.map_infer(
  File "pandas\_libs\lib.pyx", line 2834, in pandas._libs.lib.map_infer
  File "C:\Users\Michael\Documents\GitHub\ssicsync\models\summaryModel\trainingSummaryModel.py", line 68, in <lambda>
    df_input['llm_output_llama3.1'] = df_input['Notes Page Content'].apply(lambda x: summarize_business_activity(x))
  File "C:\Users\Michael\Documents\GitHub\ssicsync\models\summaryModel\trainingSummaryModel.py", line 22, in summarize_business_activity
    response = ollama.chat(model=model_name, messages=[
  File "C:\Users\Michael\AppData\Roaming\Python\Python310\site-packages\ollama\_client.py", line 235, in chat
    return self._request_stream(
  File "C:\Users\Michael\AppData\Roaming\Python\Python310\site-packages\ollama\_client.py", line 98, in _request_stream
    return self._stream(*args, **kwargs) if stream else self._request(*args, **kwargs).json()
  File "C:\Users\Michael\AppData\Roaming\Python\Python310\site-packages\ollama\_client.py", line 69, in _request
    response = self._client.request(method, url, **kwargs)
  File "C:\Users\Michael\AppData\Roaming\Python\Python310\site-packages\httpx\_client.py", line 827, in request
    return self.send(request, auth=auth, follow_redirects=follow_redirects)
  File "C:\Users\Michael\AppData\Roaming\Python\Python310\site-packages\httpx\_client.py", line 914, in send
    response = self._send_handling_auth(
  File "C:\Users\Michael\AppData\Roaming\Python\Python310\site-packages\httpx\_client.py", line 942, in _send_handling_auth
    response = self._send_handling_redirects(
  File "C:\Users\Michael\AppData\Roaming\Python\Python310\site-packages\httpx\_client.py", line 979, in _send_handling_redirects
    response = self._send_single_request(request)
  File "C:\Users\Michael\AppData\Roaming\Python\Python310\site-packages\httpx\_client.py", line 1015, in _send_single_request
    response = transport.handle_request(request)
  File "C:\Users\Michael\AppData\Roaming\Python\Python310\site-packages\httpx\_transports\default.py", line 232, in handle_request
    with map_httpcore_exceptions():
  File "C:\Program Files\Python310\lib\contextlib.py", line 153, in __exit__
    self.gen.throw(typ, value, traceback)
  File "C:\Users\Michael\AppData\Roaming\Python\Python310\site-packages\httpx\_transports\default.py", line 86, in map_httpcore_exceptions
    raise mapped_exc(message) from exc
httpx.ConnectError: [WinError 10061] No connection could be made because the target machine actively refused it
