2024-08-22 03:15:24,347 - INFO - Start code execution ...
2024-08-22 03:23:19,356 - ERROR - Uncaught exception
Traceback (most recent call last):
  File "C:\Users\Michael\Documents\GitHub\ssicsync\main.py", line 22, in <module>
    modelResults.runValidatingClassificationModel(logger)
  File "C:\Users\Michael\Documents\GitHub\ssicsync\controller.py", line 94, in runValidatingClassificationModel
    validatingClassificationModel(self, logger)
  File "C:\Users\Michael\Documents\GitHub\ssicsync\models\classificationModel\validatingClassificationModel.py", line 387, in validatingClassificationModel
    modelValidationFINAL_df.loc[modelValidationFINAL_df['SSIC 2'] == '00n', 'SSIC 2'] = np.NaN
  File "C:\Users\Michael\Documents\GitHub\ssicsync\models\classificationModel\validatingClassificationModel.py", line 387, in validatingClassificationModel
    modelValidationFINAL_df.loc[modelValidationFINAL_df['SSIC 2'] == '00n', 'SSIC 2'] = np.NaN
  File "C:\Program Files\Python310\lib\bdb.py", line 90, in trace_dispatch
    return self.dispatch_line(frame)
  File "C:\Program Files\Python310\lib\bdb.py", line 115, in dispatch_line
    if self.quitting: raise BdbQuit
bdb.BdbQuit
