2024-09-04 02:22:43,485 - INFO - Start code execution ...
2024-09-04 02:22:43,486 - INFO - Summary model: fb_bart_tfidf, Classification model: Section, Results level: Section, Top N: 3
2024-09-04 02:22:59,460 - INFO - Model classification completed. CSV file generated for Streamlit.
2024-09-04 02:22:59,492 - ERROR - Uncaught exception
Traceback (most recent call last):
  File "C:\Users\Michael\Documents\GitHub\ssicsync\main.py", line 40, in <module>
    modelResults.runValidatingClassificationModel(logger, ssic_detailed_def_filepath, ssic_alpha_index_filepath, companies_filepath)
  File "C:\Users\Michael\Documents\GitHub\ssicsync\controller.py", line 42, in runValidatingClassificationModel
    validatingClassificationModel(self, logger, ssic_detailed_def_filepath, ssic_alpha_index_filepath, companies_filepath)
  File "C:\Users\Michael\Documents\GitHub\ssicsync\models\classificationModel\validatingClassificationModel.py", line 623, in validatingClassificationModel
    with pd.ExcelWriter(overallResults_filepath, engine='openpyxl') as writer:
  File "C:\Users\Michael\AppData\Roaming\Python\Python310\site-packages\pandas\io\excel\_openpyxl.py", line 60, in __init__
    super().__init__(
  File "C:\Users\Michael\AppData\Roaming\Python\Python310\site-packages\pandas\io\excel\_base.py", line 1219, in __init__
    self._handles = get_handle(
  File "C:\Users\Michael\AppData\Roaming\Python\Python310\site-packages\pandas\io\common.py", line 868, in get_handle
    handle = open(handle, ioargs.mode)
PermissionError: [Errno 13] Permission denied: 'results/results_summaryModelfb_bart_tfidf_classificationModelSection_resultsSection_top3.xlsx'
