2024-08-21 22:39:00,850 - INFO - Start code execution.
2024-08-21 23:49:31,516 - ERROR - Uncaught exception
Traceback (most recent call last):
  File "C:\Users\Michael\Documents\GitHub\ssicsync\main.py", line 20, in <module>
    modelResults.runValidatingClassificationModel(logger)
  File "C:\Users\Michael\Documents\GitHub\ssicsync\controller.py", line 92, in runValidatingClassificationModel
    validatingClassificationModel(self, logger)
  File "C:\Users\Michael\Documents\GitHub\ssicsync\models\classificationModel\validatingClassificationModel.py", line 298, in validatingClassificationModel
    # ('Section', 'Division', 'Group', 'Class', 'Sub-class')
  File "C:\Users\Michael\Documents\GitHub\ssicsync\models\classificationModel\validatingClassificationModel.py", line 298, in validatingClassificationModel
    # ('Section', 'Division', 'Group', 'Class', 'Sub-class')
  File "C:\Program Files\Python310\lib\bdb.py", line 90, in trace_dispatch
    return self.dispatch_line(frame)
  File "C:\Program Files\Python310\lib\bdb.py", line 115, in dispatch_line
    if self.quitting: raise BdbQuit
bdb.BdbQuit
