2024-08-23 12:17:49,081 - INFO - Start code execution ...
2024-08-23 12:27:33,964 - ERROR - Uncaught exception
Traceback (most recent call last):
  File "C:\Users\Michael\Documents\GitHub\ssicsync\main.py", line 27, in <module>
    modelResults.runTrainingSummaryModel(logger)
  File "C:\Users\Michael\Documents\GitHub\ssicsync\controller.py", line 98, in runTrainingSummaryModel
    trainingSummaryModel(self, logger)
  File "C:\Users\Michael\Documents\GitHub\ssicsync\models\summaryModel\trainingSummaryModel.py", line 38, in trainingSummaryModel
    summarizer_philschmid_bart = pipeline("summarization", model="philschmid/bart-large-cnn-samsum", device=device)
  File "C:\Users\Michael\AppData\Roaming\Python\Python310\site-packages\transformers\pipelines\__init__.py", line 906, in pipeline
    framework, model = infer_framework_load_model(
  File "C:\Users\Michael\AppData\Roaming\Python\Python310\site-packages\transformers\pipelines\base.py", line 296, in infer_framework_load_model
    raise ValueError(
ValueError: Could not load model philschmid/bart-large-cnn-samsum with any of the following classes: (<class 'transformers.models.auto.modeling_auto.AutoModelForSeq2SeqLM'>, <class 'transformers.models.auto.modeling_tf_auto.TFAutoModelForSeq2SeqLM'>, <class 'transformers.models.bart.modeling_bart.BartForConditionalGeneration'>, <class 'transformers.models.bart.modeling_tf_bart.TFBartForConditionalGeneration'>). See the original errors:

while loading with AutoModelForSeq2SeqLM, an error is thrown:
Traceback (most recent call last):
  File "C:\Users\Michael\AppData\Roaming\Python\Python310\site-packages\transformers\pipelines\base.py", line 283, in infer_framework_load_model
    model = model_class.from_pretrained(model, **kwargs)
  File "C:\Users\Michael\AppData\Roaming\Python\Python310\site-packages\transformers\models\auto\auto_factory.py", line 563, in from_pretrained
    return model_class.from_pretrained(
  File "C:\Users\Michael\AppData\Roaming\Python\Python310\site-packages\transformers\modeling_utils.py", line 3380, in from_pretrained
    resolved_archive_file = cached_file(
  File "C:\Users\Michael\AppData\Roaming\Python\Python310\site-packages\transformers\utils\hub.py", line 399, in cached_file
    resolved_file = hf_hub_download(
  File "C:\Users\Michael\AppData\Roaming\Python\Python310\site-packages\huggingface_hub\utils\_validators.py", line 114, in _inner_fn
    return fn(*args, **kwargs)
  File "C:\Users\Michael\AppData\Roaming\Python\Python310\site-packages\huggingface_hub\file_download.py", line 1221, in hf_hub_download
    return _hf_hub_download_to_cache_dir(
  File "C:\Users\Michael\AppData\Roaming\Python\Python310\site-packages\huggingface_hub\file_download.py", line 1367, in _hf_hub_download_to_cache_dir
    _download_to_tmp_and_move(
  File "C:\Users\Michael\AppData\Roaming\Python\Python310\site-packages\huggingface_hub\file_download.py", line 1884, in _download_to_tmp_and_move
    http_get(
  File "C:\Users\Michael\AppData\Roaming\Python\Python310\site-packages\huggingface_hub\file_download.py", line 542, in http_get
    temp_file.write(chunk)
OSError: [Errno 28] No space left on device

while loading with TFAutoModelForSeq2SeqLM, an error is thrown:
Traceback (most recent call last):
  File "C:\Users\Michael\AppData\Roaming\Python\Python310\site-packages\transformers\pipelines\base.py", line 283, in infer_framework_load_model
    model = model_class.from_pretrained(model, **kwargs)
  File "C:\Users\Michael\AppData\Roaming\Python\Python310\site-packages\transformers\models\auto\auto_factory.py", line 563, in from_pretrained
    return model_class.from_pretrained(
  File "C:\Users\Michael\AppData\Roaming\Python\Python310\site-packages\transformers\modeling_tf_utils.py", line 2871, in from_pretrained
    raise EnvironmentError(
OSError: philschmid/bart-large-cnn-samsum does not appear to have a file named tf_model.h5 but there is a file for PyTorch weights. Use `from_pt=True` to load this model from those weights.

while loading with BartForConditionalGeneration, an error is thrown:
Traceback (most recent call last):
  File "C:\Users\Michael\AppData\Roaming\Python\Python310\site-packages\transformers\pipelines\base.py", line 283, in infer_framework_load_model
    model = model_class.from_pretrained(model, **kwargs)
  File "C:\Users\Michael\AppData\Roaming\Python\Python310\site-packages\transformers\modeling_utils.py", line 3380, in from_pretrained
    resolved_archive_file = cached_file(
  File "C:\Users\Michael\AppData\Roaming\Python\Python310\site-packages\transformers\utils\hub.py", line 399, in cached_file
    resolved_file = hf_hub_download(
  File "C:\Users\Michael\AppData\Roaming\Python\Python310\site-packages\huggingface_hub\utils\_validators.py", line 114, in _inner_fn
    return fn(*args, **kwargs)
  File "C:\Users\Michael\AppData\Roaming\Python\Python310\site-packages\huggingface_hub\file_download.py", line 1221, in hf_hub_download
    return _hf_hub_download_to_cache_dir(
  File "C:\Users\Michael\AppData\Roaming\Python\Python310\site-packages\huggingface_hub\file_download.py", line 1367, in _hf_hub_download_to_cache_dir
    _download_to_tmp_and_move(
  File "C:\Users\Michael\AppData\Roaming\Python\Python310\site-packages\huggingface_hub\file_download.py", line 1884, in _download_to_tmp_and_move
    http_get(
  File "C:\Users\Michael\AppData\Roaming\Python\Python310\site-packages\huggingface_hub\file_download.py", line 542, in http_get
    temp_file.write(chunk)
OSError: [Errno 28] No space left on device

while loading with TFBartForConditionalGeneration, an error is thrown:
Traceback (most recent call last):
  File "C:\Users\Michael\AppData\Roaming\Python\Python310\site-packages\transformers\pipelines\base.py", line 283, in infer_framework_load_model
    model = model_class.from_pretrained(model, **kwargs)
  File "C:\Users\Michael\AppData\Roaming\Python\Python310\site-packages\transformers\modeling_tf_utils.py", line 2871, in from_pretrained
    raise EnvironmentError(
OSError: philschmid/bart-large-cnn-samsum does not appear to have a file named tf_model.h5 but there is a file for PyTorch weights. Use `from_pt=True` to load this model from those weights.



